<?xml version="1.0"?>
<robot xmlns:xacro="http://wiki.ros.org/xacro">
  <!--
    Base UR robot series xacro macro.

    NOTE: this is NOT a URDF. It cannot directly be loaded by consumers
    expecting a flattened '.urdf' file. See the top-level '.xacro' for that
    (but note: that .xacro must still be processed by the xacro command).

    For use in '.launch' files: use one of the 'load_urX.launch' convenience
    launch files.

    This file models the base kinematic chain of a UR robot, which then gets
    parameterised by various configuration files to convert it into a UR3(e),
    UR5(e), UR10(e) or UR16e.

    NOTE: the default kinematic parameters (ie: link lengths, frame locations,
    offets, etc) do not correspond to any particular robot. They are defaults
    only. There WILL be non-zero offsets between the Forward Kinematics results
    in TF (ie: robot_state_publisher) and the values reported by the Teach
    Pendant.

    For accurate (and robot-specific) transforms, the 'kinematics_parameters_file'
    parameter MUST point to a .yaml file containing the appropriate values for
    the targetted robot.

    If using the UniversalRobots/Universal_Robots_ROS_Driver, follow the steps
    described in the readme of that repository to extract the kinematic
    calibration from the controller and generate the required .yaml file.

    Main author of the migration to yaml configs: Ludovic Delval.

    Contributors to previous versions (in no particular order):

     - Felix Messmer
     - Kelsey Hawkins
     - Wim Meeussen
     - Shaun Edwards
     - Nadia Hammoudeh Garcia
     - Dave Hershberger
     - G. vd. Hoorn
     - Philip Long
     - Dave Coleman
     - Miguel Prada
     - Mathias Luedtke
     - Marcel Schnirring
     - Felix von Drigalski
     - Felix Exner
     - Jimmy Da Silva
     - Ajit Krisshna N L
     - Muhammad Asif Rana
  -->

  <xacro:include filename="$(find ur_description)/urdf/inc/ur_transmissions.xacro" />
  <xacro:include filename="$(find ur_description)/urdf/inc/ur_common.xacro" />

  <xacro:macro name="ur_robot" params="
    prefix
    joint_limits_parameters_file
    kinematics_parameters_file
    physical_parameters_file
    visual_parameters_file
    transmission_hw_interface:=hardware_interface/PositionJointInterface
    safety_limits:=false
    safety_pos_margin:=0.15
    safety_k_position:=20"
  >
    <!-- Load configuration data from the provided .yaml files -->
    <xacro:read_model_data
      joint_limits_parameters_file="${joint_limits_parameters_file}" 
      kinematics_parameters_file="${kinematics_parameters_file}"
      physical_parameters_file="${physical_parameters_file}"
      visual_parameters_file="${visual_parameters_file}"/>

    <!-- Add URDF transmission elements (for ros_control) -->
    <xacro:ur_arm_transmission prefix="${prefix}" hw_interface="${transmission_hw_interface}" />

    <!-- links: main serial chain -->
    <link
      name="${prefix}base_link">
      <inertial>
        <origin
          xyz="-2.77555756156289E-17 -6.93889390390723E-18 0.0147527451068121"
          rpy="0 0 0" />
        <mass
          value="0.825861073097743" />
        <inertia
          ixx="0.00208027891140235"
          ixy="7.18819952308587E-19"
          ixz="-3.83671593666765E-19"
          iyy="0.00208027891140234"
          iyz="1.21427799633453E-18"
          izz="0.00391932737987958" />
      </inertial>
      <visual>
        <origin
          xyz="0 0 0"
          rpy="0 0 0" />
        <geometry>
          <mesh
            filename="package://al_arm_2_4/meshes/base_link.STL" />
        </geometry>
        <material
          name="">
          <color
            rgba="0.792156862745098 0.819607843137255 0.933333333333333 1" />
        </material>
      </visual>
<!--
      <collision>
        <origin
          xyz="0 0 0"
          rpy="0 0 0" />
        <geometry>
          <mesh
            filename="package://al_arm_2_4/meshes/base_link.STL" />
        </geometry>
      </collision>
-->
    </link>
    <link
      name="${prefix}Section_1">
      <inertial>
        <origin
          xyz="-4.769589445619E-10 -0.00578107509486808 0.0864872761296607"
          rpy="0 0 0" />
        <mass
          value="2.20704513466782" />
        <inertia
          ixx="0.00972749157915772"
          ixy="-8.99674275653841E-10"
          ixz="4.47374745600098E-10"
          iyy="0.00958414619563909"
          iyz="0.000299996856367023"
          izz="0.00557677453899357" />
      </inertial>
      <visual>
        <origin
          xyz="0 0 0"
          rpy="0 0 0" />
        <geometry>
          <mesh
            filename="package://al_arm_2_4/meshes/Section_1.STL" />
        </geometry>
        <material
          name="">
          <color
            rgba="0.501960784313725 0.501960784313725 1 1" />
        </material>
      </visual>
<!--
      <collision>
        <origin
          xyz="0 0 0"
          rpy="0 0 0" />
        <geometry>
          <mesh
            filename="package://al_arm_2_4/meshes/Section_1.STL" />
        </geometry>
      </collision>
-->
    </link>
    <joint
      name="${prefix}shoulder_pan_joint"
      type="revolute">
      <origin
        xyz="0 0 0.0427"
        rpy="0 0 0" />
      <parent
        link="${prefix}base_link" />
      <child
        link="${prefix}Section_1" />
      <axis
        xyz="0 0 1" />
      <limit
        lower="-${2*pi}"
        upper="${2*pi}"
        effort="0"
        velocity="0" />
    </joint>
    <link
      name="${prefix}Section_2">
      <inertial>
        <origin
          xyz="0.00569024618398725 -0.0592330307348451 0.0847722705633866"
          rpy="0 0 0" />
        <mass
          value="2.87379999776765" />
        <inertia
          ixx="0.0119233315947595"
          ixy="3.28719549360251E-05"
          ixz="8.97711261832225E-06"
          iyy="0.0115840982517504"
          iyz="-9.32165517083273E-05"
          izz="0.00639031852495258" />
      </inertial>
      <visual>
        <origin
          xyz="0 0 0"
          rpy="0 0 0" />
        <geometry>
          <mesh
            filename="package://al_arm_2_4/meshes/Section_2.STL" />
        </geometry>
        <material
          name="">
          <color
            rgba="0.501960784313725 0.501960784313725 1 1" />
        </material>
      </visual>
<!--
      <collision>
        <origin
          xyz="0 0 0"
          rpy="0 0 0" />
        <geometry>
          <mesh
            filename="package://al_arm_2_4/meshes/Section_2.STL" />
        </geometry>
      </collision>
-->
    </link>
    <joint
      name="${prefix}shoulder_lift_joint"
      type="revolute">
      <origin
        xyz="0 -0.05987 0.11"
        rpy="1.5708 -1.5708 0" />
      <parent
        link="${prefix}Section_1" />
      <child
        link="${prefix}Section_2" />
      <axis
        xyz="0 0 1" />
      <limit
        lower="-${2*pi}"
        upper="${2*pi}"
        effort="0"
        velocity="0" />
    </joint>
    <link
      name="${prefix}Section_3">
      <inertial>
        <origin
          xyz="0.0173648639387132 0.0912076643926963 0.0500626667440319"
          rpy="0 0 0" />
        <mass
          value="1.92709928656712" />
        <inertia
          ixx="0.00368998945777063"
          ixy="3.05076380336817E-05"
          ixz="1.16559983695196E-05"
          iyy="0.00323465061568845"
          iyz="-0.000174745483419691"
          izz="0.00260488915737105" />
      </inertial>
      <visual>
        <origin
          xyz="-0.02 0 0"
          rpy="0 0 0" />
        <geometry>
          <mesh
            filename="package://al_arm_2_4/meshes/Section_3.STL" />
        </geometry>
        <material
          name="">
          <color
            rgba="0.501960784313725 0.501960784313725 1 1" />
        </material>
      </visual>
<!--
      <collision>
        <origin
          xyz="-0.02 0 0"
          rpy="0 0 0" />
        <geometry>
          <mesh
            filename="package://al_arm_2_4/meshes/Section_3.STL" />
        </geometry>
      </collision>
-->
    </link>
    <joint
      name="${prefix}elbow_joint"
      type="revolute">
      <origin
        xyz="0.02 -0.246 0"
        rpy="3.1416 0 0" />
      <parent
        link="${prefix}Section_2" />
      <child
        link="${prefix}Section_3" />
      <axis
        xyz="0 0 1" />
      <limit
        lower="-${2*pi}"
        upper="${2*pi}"
        effort="0"
        velocity="0" />
    </joint>
    <link
      name="${prefix}Section_4">
      <inertial>
        <origin
          xyz="-0.000500524936368707 -0.00715552055742108 0.0398520497439656"
          rpy="0 0 0" />
        <mass
          value="0.719205488845405" />
        <inertia
          ixx="0.00198283415215535"
          ixy="-6.40311421072341E-05"
          ixz="7.24876225545178E-06"
          iyy="0.00107141913691535"
          iyz="0.000103682909011202"
          izz="0.00177485843278576" />
      </inertial>
      <visual>
        <origin
          xyz="0 0 0"
          rpy="0 0 0" />
        <geometry>
          <mesh
            filename="package://al_arm_2_4/meshes/Section_4.STL" />
        </geometry>
        <material
          name="">
          <color
            rgba="0.501960784313725 0.501960784313725 1 1" />
        </material>
      </visual>
<!--
      <collision>
        <origin
          xyz="0 0 0"
          rpy="0 0 0" />
        <geometry>
          <mesh
            filename="package://al_arm_2_4/meshes/Section_4.STL" />
        </geometry>
      </collision>
-->
    </link>
    <joint
      name="${prefix}wrist_1_joint"
      type="revolute">
      <origin
        xyz="-0.01 0.23734 0.12"
        rpy="0 0 0.066603" />
      <parent
        link="${prefix}Section_3" />
      <child
        link="${prefix}Section_4" />
      <axis
        xyz="0 0 -1" />
      <limit
        lower="-${2*pi}"
        upper="${2*pi}"
        effort="0"
        velocity="0" />
    </joint>
    <link
      name="${prefix}Section_5">
      <inertial>
        <origin
          xyz="0.00534097882409715 0.00478808006080828 0.0398529181094507"
          rpy="0 0 0" />
        <mass
          value="0.719208015630497" />
        <inertia
          ixx="0.00147703626332574"
          ixy="-0.000457449746343102"
          ixz="-7.73905050070936E-05"
          iyy="0.00157721702760716"
          iyz="-6.93786711792569E-05"
          izz="0.00177485843382113" />
      </inertial>
      <visual>
        <origin
          xyz="0 0 0"
          rpy="0 0 0" />
        <geometry>
          <mesh
            filename="package://al_arm_2_4/meshes/Section_5.STL" />
        </geometry>
        <material
          name="">
          <color
            rgba="0.501960784313725 0.501960784313725 1 1" />
        </material>
      </visual>
<!--
      <collision>
        <origin
          xyz="0 0 0"
          rpy="0 0 0" />
        <geometry>
          <mesh
            filename="package://al_arm_2_4/meshes/Section_5.STL" />
        </geometry>
      </collision>
-->
    </link>
    <joint
      name="${prefix}wrist_2_joint"
      type="revolute">
      <origin
        xyz="0.0041845 0.06 0.06"
        rpy="${-pi/2} ${-0.74+pi} -0.05" />
      <parent
        link="${prefix}Section_4" />
      <child
        link="${prefix}Section_5" />
      <axis
        xyz="0 0 -1" />
      <limit
        lower="-${2*pi}"
        upper="${2*pi}"
        effort="0"
        velocity="0" />
    </joint>
    <link
      name="${prefix}EOAT">
      <inertial>
        <origin
          xyz="-0.00503974917427097 -4.16333634234434E-17 0.0809804391232777"
          rpy="0 0 0" />
        <mass
          value="1.06840448399365" />
        <inertia
          ixx="0.00483261590021105"
          ixy="-1.86459946519464E-19"
          ixz="-0.000616134654859444"
          iyy="0.00518291038448933"
          iyz="-9.75781955236954E-19"
          izz="0.00115981481925935" />
      </inertial>
      <visual>
        <origin
          xyz="0 0 0"
          rpy="0 0 0" />
        <geometry>
          <mesh
            filename="package://al_arm_2_4/meshes/EOAT.STL" />
        </geometry>
        <material
          name="">
          <color
            rgba="0.792156862745098 0.819607843137255 0.933333333333333 1" />
        </material>
      </visual>
<!--
      <collision>
        <origin
          xyz="0 0 0"
          rpy="0 0 0" />
        <geometry>
          <mesh
            filename="package://al_arm_2_4/meshes/EOAT.STL" />
        </geometry>
      </collision>
-->
    </link>
    <joint
      name="${prefix}wrist_3_joint"
      type="revolute">
      <origin
        xyz="-0.044676 -0.040051 0.06"
        rpy="2.3 ${1.5708-pi} ${-pi/2}" />
      <parent
        link="${prefix}Section_5" />
      <child
        link="${prefix}EOAT" />
      <axis
        xyz="0 0 1" />
      <limit
        lower="-${2*pi}"
        upper="${2*pi}"
        effort="0"
        velocity="0" />
    </joint>

    <!-- ROS-Industrial 'base' frame: base_link to UR 'Base' Coordinates transform -->
    <link name="${prefix}base"/>
    <joint name="${prefix}base_link-base_fixed_joint" type="fixed">
      <!-- Note the rotation over Z of pi radians: as base_link is REP-103
           aligned (ie: has X+ forward, Y+ left and Z+ up), this is needed
           to correctly align 'base' with the 'Base' coordinate system of
           the UR controller.
      -->
      <origin xyz="0 0 0" rpy="0 0 ${pi}"/>
      <parent link="${prefix}base_link"/>
      <child link="${prefix}base"/>
    </joint>

    <!-- ROS-Industrial 'flange' frame: attachment point for EEF models -->
    <link name="${prefix}flange" />
    <joint name="${prefix}wrist_3-flange" type="fixed">
      <parent link="${prefix}Section_5" />
      <child link="${prefix}flange" />
      <origin xyz="0 0 0" rpy="0 ${-pi/2.0} ${-pi/2.0}" />
    </joint>

    <!-- ROS-Industrial 'tool0' frame: all-zeros tool frame -->
    <link name="${prefix}tool0"/>
    <joint name="${prefix}flange-tool0" type="fixed">
      <!-- default toolframe: X+ left, Y+ up, Z+ front -->
      <origin xyz="0 0 0" rpy="${pi/2.0} 0 ${pi/2.0}"/>
      <parent link="${prefix}EOAT"/>
      <child link="${prefix}tool0"/>
    </joint>
  </xacro:macro>
</robot>
